{'code': ExecutionFailed, 'message': [{"exit_code":1,"error_message":"Execution failed with error: [stderr]Traceback (most recent call last):\n[stderr]  File \"<string>\", line 197, in <module>\n[stderr]  File \"<string>\", line 115, in strip_stack_of_azureml_layers\n[stderr]  File \"/azureml-envs/azureml_ba9520bf386d662001eeb9523395794e/lib/python3.6/traceback.py\", line 117, in format_exception\n[stderr]    type(value), value, tb, limit=limit).format(chain=chain))\n[stderr]  File \"/azureml-envs/azureml_ba9520bf386d662001eeb9523395794e/lib/python3.6/traceback.py\", line 497, in __init__\n[stderr]    capture_locals=capture_locals)\n[stderr]  File \"/azureml-envs/azureml_ba9520bf386d662001eeb9523395794e/lib/python3.6/traceback.py\", line 358, in extract\n[stderr]    f.line\n[stderr]  File \"/azureml-envs/azureml_ba9520bf386d662001eeb9523395794e/lib/python3.6/traceback.py\", line 282, in line\n[stderr]    self._line = linecache.getline(self.filename, self.lineno).strip()\n[stderr]  File \"/azureml-envs/azureml_ba9520bf386d662001eeb9523395794e/lib/python3.6/linecache.py\", line 16, in getline\n[stderr]    lines = getlines(filename, module_globals)\n[stderr]  File \"/azureml-envs/azureml_ba9520bf386d662001eeb9523395794e/lib/python3.6/linecache.py\", line 47, in getlines\n[stderr]    return updatecache(filename, module_globals)\n[stderr]  File \"/azureml-envs/azureml_ba9520bf386d662001eeb9523395794e/lib/python3.6/linecache.py\", line 137, in updatecache\n[stderr]    lines = fp.readlines()\n[stderr]  File \"/azureml-envs/azureml_ba9520bf386d662001eeb9523395794e/lib/python3.6/codecs.py\", line 321, in decode\n[stderr]    (result, consumed) = self._buffer_decode(data, self.errors, final)\n[stderr]UnicodeDecodeError: 'utf-8' codec can't decode byte 0x91 in position 692: invalid start byte\n","process_name":"/azureml-envs/azureml_ba9520bf386d662001eeb9523395794e/bin/python","error_file":"user_logs/std_log.txt"}], 'target': , 'category': UserError, 'error_details': [{'key': exit_codes, 'value': 1}, ], 'inner_error': null}